Traceback (most recent call last):
  File "/home/runner/micromamba/envs/kerchunk-cookbook/lib/python3.13/site-packages/jupyter_core/utils/__init__.py", line 154, in wrapped
    asyncio.get_running_loop()
    ~~~~~~~~~~~~~~~~~~~~~~~~^^
RuntimeError: no running event loop

During handling of the above exception, another exception occurred:

Traceback (most recent call last):
  File "/home/runner/micromamba/envs/kerchunk-cookbook/lib/python3.13/site-packages/jupyter_cache/executors/utils.py", line 58, in single_nb_execution
    executenb(
    ~~~~~~~~~^
        nb,
        ^^^
    ...<4 lines>...
        **kwargs,
        ^^^^^^^^^
    )
    ^
  File "/home/runner/micromamba/envs/kerchunk-cookbook/lib/python3.13/site-packages/nbclient/client.py", line 1319, in execute
    return NotebookClient(nb=nb, resources=resources, km=km, **kwargs).execute()
           ~~~~~~~~~~~~~~~~~~~~~~~~~~~~~~~~~~~~~~~~~~~~~~~~~~~~~~~~~~~~~~~~~~~^^
  File "/home/runner/micromamba/envs/kerchunk-cookbook/lib/python3.13/site-packages/jupyter_core/utils/__init__.py", line 158, in wrapped
    return loop.run_until_complete(inner)
           ~~~~~~~~~~~~~~~~~~~~~~~^^^^^^^
  File "/home/runner/micromamba/envs/kerchunk-cookbook/lib/python3.13/asyncio/base_events.py", line 725, in run_until_complete
    return future.result()
           ~~~~~~~~~~~~~^^
  File "/home/runner/micromamba/envs/kerchunk-cookbook/lib/python3.13/site-packages/nbclient/client.py", line 709, in async_execute
    await self.async_execute_cell(
        cell, index, execution_count=self.code_cells_executed + 1
    )
  File "/home/runner/micromamba/envs/kerchunk-cookbook/lib/python3.13/site-packages/nbclient/client.py", line 1062, in async_execute_cell
    await self._check_raise_for_error(cell, cell_index, exec_reply)
  File "/home/runner/micromamba/envs/kerchunk-cookbook/lib/python3.13/site-packages/nbclient/client.py", line 918, in _check_raise_for_error
    raise CellExecutionError.from_cell_and_msg(cell, exec_reply_content)
nbclient.exceptions.CellExecutionError: An error occurred while executing the following cell:
------------------
# Create a list of reference json files
output_files = [
    f"{temp_dir}/{f.strip('.nc').split('/')[-1]}.json" for f in first_24_hrs
]

# combine individual references into single consolidated reference
mzz = MultiZarrToZarr(
    output_files,
    concat_dims=["time"],
    identical_dims=["y", "x"],
    remote_protocol="s3",
    remote_options={"anon": True},
    coo_map={"time": "cf:time"},
)
# save translate reference in memory for later visualization
multi_kerchunk = mzz.translate()

# Write kerchunk .json record.
output_fname = "ARG_combined.json"
with open(f"{output_fname}", "wb") as f:
    f.write(ujson.dumps(multi_kerchunk).encode())
------------------


[31m---------------------------------------------------------------------------[39m
[31mRuntimeError[39m                              Traceback (most recent call last)
[36mCell[39m[36m [39m[32mIn[8][39m[32m, line 16[39m
[32m      7[39m mzz = MultiZarrToZarr(
[32m      8[39m     output_files,
[32m      9[39m     concat_dims=[[33m"[39m[33mtime[39m[33m"[39m],
[32m   (...)[39m[32m     13[39m     coo_map={[33m"[39m[33mtime[39m[33m"[39m: [33m"[39m[33mcf:time[39m[33m"[39m},
[32m     14[39m )
[32m     15[39m [38;5;66;03m# save translate reference in memory for later visualization[39;00m
[32m---> [39m[32m16[39m multi_kerchunk = [43mmzz[49m[43m.[49m[43mtranslate[49m[43m([49m[43m)[49m
[32m     18[39m [38;5;66;03m# Write kerchunk .json record.[39;00m
[32m     19[39m output_fname = [33m"[39m[33mARG_combined.json[39m[33m"[39m

[36mFile [39m[32m~/micromamba/envs/kerchunk-cookbook/lib/python3.13/site-packages/kerchunk/combine.py:647[39m, in [36mMultiZarrToZarr.translate[39m[34m(self, filename, storage_options)[39m
[32m    645[39m     [38;5;28mself[39m.first_pass()
[32m    646[39m [38;5;28;01mif[39;00m [32m2[39m [38;5;129;01mnot[39;00m [38;5;129;01min[39;00m [38;5;28mself[39m.done:
[32m--> [39m[32m647[39m     [38;5;28;43mself[39;49m[43m.[49m[43mstore_coords[49m[43m([49m[43m)[49m
[32m    648[39m [38;5;28;01mif[39;00m [32m3[39m [38;5;129;01mnot[39;00m [38;5;129;01min[39;00m [38;5;28mself[39m.done:
[32m    649[39m     [38;5;28mself[39m.second_pass()

[36mFile [39m[32m~/micromamba/envs/kerchunk-cookbook/lib/python3.13/site-packages/kerchunk/combine.py:473[39m, in [36mMultiZarrToZarr.store_coords[39m[34m(self)[39m
[32m    470[39m [38;5;28mself[39m.out.update(kv)
[32m    471[39m logger.debug([33m"[39m[33mWritten coordinates[39m[33m"[39m)
[32m--> [39m[32m473[39m metadata = [43masyncio[49m[43m.[49m[43mrun[49m[43m([49m[38;5;28;43mself[39;49m[43m.[49m[43m_read_meta_files[49m[43m([49m[43mm[49m[43m,[49m[43m [49m[43m[[49m[33;43m"[39;49m[33;43m.zgroup[39;49m[33;43m"[39;49m[43m,[49m[43m [49m[33;43m"[39;49m[33;43m.zattrs[39;49m[33;43m"[39;49m[43m][49m[43m)[49m[43m)[49m
[32m    474[39m [38;5;28mself[39m.out.update(metadata)
[32m    475[39m logger.debug([33m"[39m[33mWritten global metadata[39m[33m"[39m)

[36mFile [39m[32m~/micromamba/envs/kerchunk-cookbook/lib/python3.13/asyncio/runners.py:191[39m, in [36mrun[39m[34m(main, debug, loop_factory)[39m
[32m    161[39m [38;5;250m[39m[33;03m"""Execute the coroutine and return the result.[39;00m
[32m    162[39m 
[32m    163[39m [33;03mThis function runs the passed coroutine, taking care of[39;00m
[32m   (...)[39m[32m    187[39m [33;03m    asyncio.run(main())[39;00m
[32m    188[39m [33;03m"""[39;00m
[32m    189[39m [38;5;28;01mif[39;00m events._get_running_loop() [38;5;129;01mis[39;00m [38;5;129;01mnot[39;00m [38;5;28;01mNone[39;00m:
[32m    190[39m     [38;5;66;03m# fail fast with short traceback[39;00m
[32m--> [39m[32m191[39m     [38;5;28;01mraise[39;00m [38;5;167;01mRuntimeError[39;00m(
[32m    192[39m         [33m"[39m[33masyncio.run() cannot be called from a running event loop[39m[33m"[39m)
[32m    194[39m [38;5;28;01mwith[39;00m Runner(debug=debug, loop_factory=loop_factory) [38;5;28;01mas[39;00m runner:
[32m    195[39m     [38;5;28;01mreturn[39;00m runner.run(main)

[31mRuntimeError[39m: asyncio.run() cannot be called from a running event loop

